Workbook
Name \0: #REF!
Name \a: #REF!
Name \d: #REF!
Name \m: #REF!
Name \p: '[1]Bco. Internacional'!#REF!
Name __: #REF!
Name ___A320000: #REF!
Name ___A66000: #REF!
Name ___A69000: #REF!
Name ___A70000: #REF!
Name ___A99999: #REF!
Name ___M151060: #REF!
Name ___M152040: #REF!
Name ___M152050: '[2]Det. Rec. Prov. Locales {PPC}'!#REF!
Name ___MM11055: #REF!
Name ___MM23616: #REF!
Name ___RSE1: #REF!
Name ___RSE2: #REF!
Name __A320000: [3]CoberturaSeg!$A$32009
Name __A66000: [3]CoberturaSeg!$A$65009
Name __A69000: [3]CoberturaSeg!$A$65009
Name __A70000: [3]CoberturaSeg!$A$50009
Name __A99999: [3]CoberturaSeg!$A$32009
Name __DAT1: #REF!
Name __DAT10: #REF!
Name __DAT11: #REF!
Name __DAT12: #REF!
Name __DAT13: #REF!
Name __DAT14: #REF!
Name __DAT15: #REF!
Name __DAT16: #REF!
Name __DAT17: #REF!
Name __DAT18: #REF!
Name __DAT2: #REF!
Name __DAT3: #REF!
Name __DAT4: #REF!
Name __DAT5: #REF!
Name __DAT6: #REF!
Name __DAT7: #REF!
Name __DAT8: #REF!
Name __DAT9: #REF!
Name __M151060: #REF!
Name __M152040: #REF!
Name __M152050: '[2]Det. Rec. Prov. Locales {PPC}'!#REF!
Name __MM11055: #REF!
Name __MM23616: #REF!
Name __ND1: #REF!
Name __OB98008: '[4]OBB 31-dic-00'!#REF!
Name __OB98025: '[4]OBB 31-dic-00'!#REF!
Name __Pag1: #REF!
Name __pr1: #REF!
Name __RSE1: #REF!
Name __RSE2: #REF!
Name _02: #REF!
Name _10: #REF!
Name _1001: #REF!
Name _100101: #REF!
Name _10010101: #REF!
Name _1001010101: #REF!
Name _1001010102: #REF!

Sheet 136.07
N3: Preparado por: | O3: Revisado por: | P3: Ref.
N4: XX | O4: XX | P4: 136.07
B6: COMPAÑÍA MODELO S.A.
B7: VALIDACIÓN DE TRANSACCIONES CON COMPAÑÍAS FANTASMA
B8: AL 31 DE DICIEMBRE DE 20XX
B9: FECHA DE CORTE: _/_/20XX
B12: Objetivo:
B14: Determinar que la Compañía no registre operaciones con empresas fantasma.
B16: Base de decisión: Materialidad
C19: Preliminar | D19: Final
B20: General | C20: XXX.XXX | D20: XXX.XXX
B21: Desempeño | C21: XXX.XXX | D21: XXX.XXX
B22: Errores Triviales | C22: XXX.XXX | D22: XXX.XXX
B24: Procedimiento:
A26: 1.- | B26: Solicitar a la Compañía el detalle de compras al _/_/20XX.
A27: 2.- | B27: Descargar el listado de empresas fantasma a la fecha de nuestra revisión. ***(Incluir fecha de descarga)
A28: 3.- | B28: Verificar que la Compañía no se encuentre realizando transacciones con Compañías fantasma.
A29: 4.- | B29: Documentar el papel de trabajo y concluir en función al objetivo.
B32: Desarrollo:
G34: *** El número de filas, así como el formato depende del detalle de compras de la Compañía Modelo S.A.
B38: Base de compras | P38: Calculos según auditoría
B39: Nro. interno | C39: Tipo | D39: Fecha | E39: Secuencial | F39: RUC del proveedor | G39: Nombre proveedor | H39: TD | I39: TC | J39: Total del documento | K39: Subtotal | L39: Base 0% | M39: Base 12 % | N39: Total IVA | P39: RUC empresa fantasma | Q39: Empresa fantasma
P40: =+IFERROR(VLOOKUP(F40,'Listado empresas fantasmas SRI'!$B$2:$B$1057,1,0),0) -> 0 | Q40: =+IF(P40=0,"No","Si") -> No
P41: =+IFERROR(VLOOKUP(F41,'Listado empresas fantasmas SRI'!$B$2:$B$1057,1,0),0) -> 0 | Q41: =+IF(P41=0,"No","Si") -> No
P42: =+IFERROR(VLOOKUP(F42,'Listado empresas fantasmas SRI'!$B$2:$B$1057,1,0),0) -> 0 | Q42: =+IF(P42=0,"No","Si") -> No
P43: =+IFERROR(VLOOKUP(F43,'Listado empresas fantasmas SRI'!$B$2:$B$1057,1,0),0) -> 0 | Q43: =+IF(P43=0,"No","Si") -> No
P44: =+IFERROR(VLOOKUP(F44,'Listado empresas fantasmas SRI'!$B$2:$B$1057,1,0),0) -> 0 | Q44: =+IF(P44=0,"No","Si") -> No
P45: =+IFERROR(VLOOKUP(F45,'Listado empresas fantasmas SRI'!$B$2:$B$1057,1,0),0) -> 0 | Q45: =+IF(P45=0,"No","Si") -> No
P46: =+IFERROR(VLOOKUP(F46,'Listado empresas fantasmas SRI'!$B$2:$B$1057,1,0),0) -> 0 | Q46: =+IF(P46=0,"No","Si") -> No
P47: =+IFERROR(VLOOKUP(F47,'Listado empresas fantasmas SRI'!$B$2:$B$1057,1,0),0) -> 0 | Q47: =+IF(P47=0,"No","Si") -> No
P48: =+IFERROR(VLOOKUP(F48,'Listado empresas fantasmas SRI'!$B$2:$B$1057,1,0),0) -> 0 | Q48: =+IF(P48=0,"No","Si") -> No
P49: =+IFERROR(VLOOKUP(F49,'Listado empresas fantasmas SRI'!$B$2:$B$1057,1,0),0) -> 0 | Q49: =+IF(P49=0,"No","Si") -> No
B53: Resumen del análisis
B55: 1) ¿Proveedor es empresa fantasma?
B57: Si | D57: =+COUNTIF(Q40:Q49,B57) -> 0
B58: No | D58: =+COUNTIF(Q41:Q50,B58) -> 9
B62: Marcas de auditoría:
B64: Información proporcionada por el cliente
B65: Cálculos de Auditoría
B67: Verificaciones:
...

Sheet Listado empresas fantasmas SRI
A1: No. | B1: RUC | C1: RAZÓN SOCIAL | D1: TIPO DE CONTRIBUYENTE | E1: ZONA | F1: OFICIO 5 DÍAS NOTIFICADO | G1: FECHA DE NOTIFICACIÓN | H1: Nro. RESOLUCIÓN | I1: FECHA NOTIFICACIÓN | J1: CALIFICACIÓN | K1: ESTADO DEL RUC | L1: FECHA INICIO CALIFICACIÓN (**) | M1: FECHA FINALIZACIÓN CALIFICACIÓN (**) | N1: RESOLUCIÓN /SENTENCIA DE BAJA | O1: FECHA DE NOTIFICACIÓN RESOLUCIÓN /SENTENCIA | P1: N° DE OFICIO DE REACTIVACIÓN DE RUC | Q1: FECHA DE NOTIFICACIÓN | R1: ACEPTA / RECHAZA | S1: FECHA DE REACTIVACIÓN | T1: INSTANCIA DE IMPUGNACION | U1: ESTADO DE LA IMPUGNACIÓN
A2: 1 | B2: 1351650526001 | C2: BRAVO ACOSTA ANSELMO RAMON | D2: PERSONA NATURAL | E2: ZONA 1 | F2: PES-GTROGEI17-00000086-M | G2: 43003 | H2: DZ1-GPNRASN17-00000003-M | I2: 43047 | J2: Persona natural con actividades supuestas / transacciones inexistentes. | K2: SUSPENDIDO | T2: - | U2: -
A3: 2 | B3: 2191711079001 | C3: CONEFACONST CIA. LTDA. | D3: SOCIEDAD | E3: ZONA 1 | F3: NAC-DNCOPEC16-00161874-M | G3: 42601.339 | H3: DZ1-GSORIFV16-00000001 | I3: 42629 | J3: Sociedad con actividades supuestas o transacciones inexistentes | K3: SUSPENDIDO | L3: 40909 | M3: 42369 | T3: - | U3: -
A4: 3 | B4: 1727082578001 | C4: CONFORME MORALES LUIS FELIPE | D4: PERSONA NATURAL | E4: ZONA 1 | F4: PES-GTROGEC17-00000089-M | G4: 43007 | H4: DZ1-GPNRASN17-00000004-M | I4: 43052 | J4: Persona natural con actividades supuestas y transacciones inexistentes. | K4: SUSPENDIDO | T4: - | U4: -
A5: 4 | B5: 0802999060001 | C5: COROZO ESTUPIÑAN MAURICIO JOSE | D5: PERSONA NATURAL | E5: ZONA 1 | F5: PES-GTROGEC17-00000087-M | G5: 43005 | H5: DZ1-GPNRASN17-00000001-M | I5: 43052 | J5: Persona natural con actividades supuestas / transacciones inexistentes. | K5: SUSPENDIDO | T5: - | U5: -
A6: 5 | B6: 2100657770001 | C6: GAMEZ MENDEZ SILVIA CARMEN | D6: PERSONA NATURAL | E6: ZONA 1 | F6: PES-GTROGEC17-00000091-M | G6: 43007 | H6: DZ1-GPNRASN17-00000005-M | I6: 43052 | J6: Persona natural con actividades supuestas / transacciones inexistentes. | K6: SUSPENDIDO | T6: - | U6: -
A7: 6 | B7: 1792444713001 | C7: INCONCIV CONSTRUCCIONES CIA. LTDA. | D7: SOCIEDAD | E7: ZONA 1 | F7: DZ1-GSOOGEV17-00000002-M | G7: 43013 | H7: DZ1-GSORASV17-00000001-M | I7: 43021 | J7: Empresa inexistente / fantasma con actividades supuestas / transacciones inexistentes. | K7: PASIVO | T7: - | U7: -
A8: 7 | B8: 1723936066001 | C8: LOPEZ CORDERO DAVID ESTEBAN | D8: PERSONA NATURAL | E8: ZONA 1 | F8: PES-GTROGEC17-00000090-M | G8: 43003 | H8: DZ1-GPNRASO17-00000001-M | I8: 43047 | J8: Persona natural con actividades supuestas / transacciones inexistentes. | K8: SUSPENDIDO | M8: 42735 | N8: NAC-RRRRRVC22-00000172 | O8: 44677 | T8: RECURSOS DE REVISION | U8: FINALIZADO POR PERÍODOS
A9: 8 | B9: 1708816614001 | C9: VARGAS ALCIVAR FRANCISCO ISIDRO | D9: PERSONA NATURAL | E9: ZONA 1 | F9: PES-GTROGEN17-00000092-M | G9: 43003 | H9: DZ1-GPNRASN17-00000006-M | I9: 43068 | J9: Persona natural con actividades supuestas / transacciones inexistentes. | K9: SUSPENDIDO | M9: 43100 | N9: NAC-RRRRRVC20-00000295 | O9: 44218 | T9: RECURSOS DE REVISION | U9: FINALIZADO POR PERÍODOS
A10: 9 | B10: 0803139435001 | C10: ZAMBRANO MENDOZA KATIUSKA JACINTA | D10: PERSONA NATURAL | E10: ZONA 1 | F10: PES-GTROGEC17-00000088-M | G10: 43004 | H10: DZ1-GPNRASN17-00000002-M | I10: 43052 | J10: Persona natural con actividades supuestas / transacciones inexistentes. | K10: SUSPENDIDO | T10: - | U10: -
A11: 10 | B11: 1500198609001 | C11: ARELLANO MAFLA HEISTEIN MENTOR | D11: PERSONA NATURAL | E11: ZONA 2 | F11: NAC-DNCOIOG16-00005398 | G11: 42685 | H11: DZ2-GTRRSAC16-00000005-M | I11: 42705 | J11: Persona natural con actividades supuestas y/o transacciones inexistentes. | K11: SUSPENDIDO | T11: RECLAMOS | U11: FINALIZADO SE RATIFICA
A12: 11 | B12: 1704462280001 | C12: ARELLANO MAFLA JUAN MILTON | D12: PERSONA NATURAL | E12: ZONA 2 | F12: NAC-DNCOIOG16-00005422 | G12: 42685 | H12: DZ2-GTRRSAC16-00000001-M | I12: 42705 | J12: Persona natural con actividades supuestas y/o transacciones inexistentes. | K12: SUSPENDIDO | T12: RECLAMOS | U12: FINALIZADO SE RATIFICA
A13: 12 | B13: 1792299519001 | C13: COMPAÑÍA DE TRANSPORTE FLUVIAL CHIROISLA CIA. LTDA. | D13: SOCIEDAD | E13: ZONA 2 | F13: NAC-DNCOPEC16-00161996-M | G13: 42601.339 | H13: DZ2-GTRRSAV15-00000001-M | I13: 42621 | J13: Empresa inexistente, fantasma con actividades supuestas y transacciones inexistentes. | K13: SUSPENDIDO | T13: - | U13: -
A14: 13 | B14: 1900100361001 | C14: ORDOÑEZ BERMEO EDGAR | D14: PERSONA NATURAL | E14: ZONA 2 | F14: NAC-DNCOIOG16-00005307 | G14: 42689 | H14: DZ2-GTRRSAC16-00000003-M | I14: 42705 | J14: Persona natural con actividades supuestas y/o transacciones inexistentes. | K14: PASIVO | T14: - | U14: -
A15: 14 | B15: 1500686827001 | C15: SALAS ARELLANO WASHINGTON OSWALDO | D15: PERSONA NATURAL | E15: ZONA 2 | F15: NAC-DNCOIOG16-00005437 | G15: 42685 | H15: DZ2-GTRRSAC16-00000004-M | I15: 42705 | J15: Persona natural con actividades supuestas y/o transacciones inexistentes. | K15: SUSPENDIDO | T15: - | U15: -
A16: 15 | B16: 1501167298001 | C16: TORRES VILLON BRYAN JOEL | D16: PERSONA NATURAL | E16: ZONA 2 | F16: DZ2-GTROGEI17-00000003-M | G16: 43027 | H16: DZ2-GTRRASC17-00000003-M | I16: 43035 | J16: Persona natural con actividades supuestas y/o transacciones inexistentes. | K16: SUSPENDIDO | T16: - | U16: -
A17: 16 | B17: 0703249664001 | C17: VILLEGAS LIMONES JOSE PATRICIO | D17: PERSONA NATURAL | E17: ZONA 2 | F17: DZ2-GTROGEI17-00000002-M | G17: 43027 | H17: DZ2-GTRRASC17-00000002-M | I17: 43035 | J17: Persona natural con actividades supuestas y/o transacciones inexistentes. | K17: SUSPENDIDO | T17: - | U17: -
A18: 17 | B18: 0701820953001 | C18: VILLON PLACENCIO HENRY WANEY | D18: PERSONA NATURAL | E18: ZONA 2 | F18: NAC-DNCOIOG16-00005393 | G18: 42685 | H18: DZ2-GTRRSAC16-00000002-M | I18: 42705 | J18: Persona natural con actividades supuestas / transacciones inexistentes. | K18: SUSPENDIDO | T18: RECLAMOS | U18: FINALIZADO SE RATIFICA
A19: 18 | B19: 0702522228001 | C19: VILLON PLASENCIO AMARILIS NOEMI | D19: PERSONA NATURAL | E19: ZONA 2 | F19: DZ2-GTROGEI17-00000001-M | G19: 43027 | H19: DZ2-GTRRASC17-00000001-M | I19: 43035 | J19: Persona natural con actividades supuestas y/o transacciones inexistentes. | K19: SUSPENDIDO | T19: - | U19: -
A20: 19 | B20: 1802731651001 | C20: CARRASCO TAMAYO RICARDO SANTIAGO | D20: PERSONA NATURAL | E20: ZONA 3 | F20: DZ3-GCEOGEC19-00000001-M | G20: 43481 | H20: DZ3-GCERASC19-00000001-M | I20: 43502 | J20: Persona natural con actividades supuestas y/o transacciones inexistentes. | K20: SUSPENDIDO | T20: - | U20: -
A21: 20 | B21: 0603912627001 | C21: CASANOVA ZAMORA TANNIA ALEXANDRA | D21: PERSONA NATURAL | E21: ZONA 3 | F21: NAC-DNCOIOG16-00005444 | G21: 42685 | H21: PCH-GTRRASN16-00000208-M | I21: 42704 | J21: Persona natural con actividades supuestas y/o transacciones inexistentes. | K21: SUSPENDIDO | T21: RECLAMOS | U21: FINALIZADO SE RATIFICA
... A26: 25 | B26: 1312832569001 | C26: ARTEAGA MACIAS CARLOS ENRIQUE | D26: PERSONA NATURAL | E26: ZONA 4 | F26: NAC-DNCOIOG16-00005330 | G26: 42685 | H26: CMA-GPNRASC16-00000001-M | I26: 42733 | J26: Persona natural con actividades supuestas y/o transacciones inexistentes. | K26: SUSPENDIDO | T26: - | U26: -
A27: 26 | B27: 1312909870001 | C27: ARTURO ORTIZ MARIA ANABEL | D27: PERSONAS NATURALES | E27: ZONA 4 | F27: DZ4-GSOORIC18-00000008-M | G27: 43297 | H27: DZ4-GSOOIOC18-00000002-M | I27: 43321 | J27: Persona natural con actividades supuestas y/o transacciones inexistentes. | K27: ACTIVO | P27: CBC-CGTOGEC20-00000001-M CBC-CGTOGEC20-00000003-M | Q27: 19/10/2020 15/12/2020 | R27: ACEPTA | S27: 44257 | T27: - | U27: -
A28: 27 | B28: 0914707765001 | C28: ASENCIO DIAZ JULIO ERNESTO | D28: PERSONA NATURAL | E28: ZONA 4 | F28: NAC-DNCOIOG16-00005427 | G28: 42685 | H28: CMA-GPNRASC16-00000002-M | I28: 42733 | J28: Persona natural con actividades supuestas y/o transacciones inexistentes. | K28: SUSPENDIDO | T28: - | U28: -
A29: 28 | B29: 1311442527001 | C29: AVILA VELASCO GREGORIO ELIAS | D29: PERSONA NATURAL | E29: ZONA 4 | F29: CJI-CGTORIC18-00000002-M | G29: 43287 | H29: DZ4-GPNMGEI18-00000002-M | I29: 43298 | J29: Persona natural con actividades supuestas y/o transacciones inexistentes. | K29: SUSPENDIDO | T29: - | U29: -
A30: 29 | B30: 1309568952001 | C30: AVILEZ VELEZ OSCAR ARTURO | D30: PERSONA NATURAL | E30: ZONA 4 | F30: PSD-GTROGEC20-00000004-M | G30: 43882 | H30: PSD-GTRRASC20-00000005-M | I30: 44133 | J30: Persona natural con actividades supuestas y/o transacciones inexistentes. | K30: SUSPENDIDO | T30: - | U30: -
A31: 30 | B31: 1391776276001 | C31: BIOCIUDAD S.A. | D31: SOCIEDAD | E31: ZONA 4 | F31: DZ4-ASOOPEC17-00000001-M | G31: 43070 | H31: DZ4-ASORASC17-00000001-M | I31: 43089 | J31: Sociedad con transacciones inexistentes | K31: PASIVO | T31: - | U31: -
A32: 31 | B32: 1310021280001 | C32: BRAVO PARRAGA RICHAR ESTALIN | D32: PERSONA NATURAL | E32: ZONA 4 | F32: NAC-DNCOIOG16-00005404 | G32: 42685 | H32: CMA-GPNRASC16-00000003-M | I32: 42733 | J32: Persona natural con actividades supuestas y/o transacciones inexistentes. | K32: SUSPENDIDO | T32: - | U32: -
A33: 32 | B33: 0802192211001 | C33: CARVAJAL CASTILLO SARA YAQUELINE | D33: PERSONA NATURAL | E33: ZONA 4 | F33: PSD-GTROGEC20-00000002-M | G33: 43882 | H33: PSD-GTRRASC20-00000001-M | I33: 44133 | J33: Persona natural con actividades supuestas y/o transacciones inexistentes. | K33: SUSPENDIDO | T33: - | U33: -
A34: 33 | B34: 1315832509001 | C34: CASTRO GONGORA PEDRO CARLOS | D34: PERSONA NATURAL | E34: ZONA 4 | F34: DZ4-GPNOGEC17-00000009-M | G34: 43005 | H34: DZ4-GPNRASC17-00000004-M | I34: 43025 | J34: Persona natural con actividades supuestas y/o transacciones inexistentes. | K34: SUSPENDIDO | T34: - | U34: -
A35: 34 | B35: 1312956376001 | C35: CEDEÑO LOOR ANGEL ENRIQUE | D35: PERSONA NATURAL | E35: ZONA 4 | F35: DZ4-APNOPEC18-00000001-M | G35: 27, 30 Y 31 DE JULIO 2018 | H35: DZ4-APNRASC19-00000001-M | I35: 43696 | J35: Persona natural con actividades supuestas e inexistentes. | K35: SUSPENDIDO | T35: - | U35: -
A36: 35 | B36: 1309067005001 | C36: CEDEÑO ZAMBRANO RAMON ANTENOR | D36: PERSONAS NATURALES | E36: ZONA 4 | F36: DZ4-GPNOGEC17-00000016-M | G36: 43006 | H36: CCH-GPNRASC17-00000002-M | I36: 43025 | J36: Persona natural con actividades supuestas / transacciones inexistentes. | K36: ACTIVO | P36: 113142018OGTN000435 | Q36: 43479 | R36: ACEPTA | S36: 43881 | T36: - | U36: -
A37: 36 | B37: 1311432668001 | C37: CHAVEZ TRIVIÑO GINA MARIUXI | D37: PERSONA NATURAL | E37: ZONA 4 | F37: NAC-DNCOIOG16-00005329 | G37: 42685 | H37: CMA-GPNRASC16-00000004-M | I37: 42705 | J37: Persona natural con actividades supuestas / transacciones inexistentes. | K37: SUSPENDIDO | T37: - | U37: -
A38: 37 | B38: 1311949166001 | C38: CHOEZ MERA VICTOR MANUEL | D38: PERSONA NATURAL | E38: ZONA 4 | F38: NAC-DNCOIOG16-00005440 | G38: 42685 | H38: DZ4-GPNRASC16-00000008-M | I38: 42733 | J38: Persona natural con actividades supuestas / transacciones inexistentes. | K38: SUSPENDIDO | T38: - | U38: -
A39: 38 | B39: 0928978956001 | C39: CHUNG LOOR KENIA VANESSA | D39: PERSONA NATURAL | E39: ZONA 4 | F39: CCH-CGTOGEC18-00000001-M | G39: 43390 | H39: CCH-CGTRASC18-00000001-M | I39: 43398 | J39: Persona natural con actividades supuestas / transacciones inexistentes. | K39: SUSPENDIDO | T39: - | U39: -
A40: 39 | B40: 1391831536001 | C40: CONSTRUCCIONES CIVIL SUAREZ & MOYA CONCISUAMO CIA.LTDA. | D40: SOCIEDAD | E40: ZONA 4 | F40: CMA-CGTOFQV17-00000072-M | G40: 43006 | H40: CMA-CGTRASV17-00000002-M | I40: 43032 | J40: Persona natural con actividades supuestas o transacciones inexistentes. | K40: PASIVO | T40: - | U40: -
A41: 40 | B41: 0907365878001 | C41: CRESPO GRANIZO WILLIAM RODOLFO | D41: PERSONA NATURAL | E41: ZONA 4 | F41: DZ4-GPNOGEC17-00000018-M | G41: 43055 | H41: DZ4-CGTRASC17-00010001-M | I41: 43066 | J41: Persona natural con actividades supuestas / transacciones inexistentes. | K41: SUSPENDIDO | T41: - | U41: -
A42: 41 | B42: 1725062986001 | C42: CUENCA ALAVA YUBER DANIEL | D42: PERSONA NATURAL | E42: ZONA 4 | F42: NAC-DNCOIOG16-00005336 | G42: 42685 | H42: DZ4-GPNRASC16-00000009-M | I42: 42706 | J42: Persona natural con actividades supuestas y/o transacciones inexistentes. | K42: SUSPENDIDO | T42: - | U42: -
A43: 42 | B43: 1312797853001 | C43: CUENCA PILAY HERNAN FREDDY | D43: PERSONA NATURAL | E43: ZONA 4 | F43: NAC-DNCOIOG16-00005335 | G43: 42685 | H43: DZ4-GPNRASC16-00000010-M | I43: 42706 | J43: Persona natural con actividades supuestas y/o transacciones inexistentes. | K43: SUSPENDIDO | T43: - | U43: -
A44: 43 | B44: 1306767508001 | C44: DE LA CRUZ CEDEÑO PEDRO JOSE | D44: PERSONA NATURAL | E44: ZONA 4 | F44: NAC-DNCOIOG16-00005438 | G44: 42685 | H44: DZ4-GPNRASC16-00000011-M | I44: 42733 | J44: Persona natural con actividades supuestas y/o transacciones inexistentes. | K44: SUSPENDIDO | T44: - | U44: -
...
