Workbook

Sheet 330.05.01
T3: Preparado por: | U3: Revisado por: | V3: Ref.
B4: COMPAÑÍA MODELO S.A. | T4: XX | U4: XX | V4: 330.05.01
B5: CONCILIACIÓN DE OBLIGACIONES FINANCIERAS CON ESTADOS FINANCIEROS
B6: AL 31 DE DICIEMBRE DE 20XX
B7: FECHA DE CORTE: _ / _ / 20XX
B10: Objetivo:
B12: Verificar la exactitud o valuación de la cuenta de obligaciones financieras al _ / _ / 20XX
B14: Base de decisión: Materialidad
C16: Preliminar | D16: Final
B17: General | C17: xxx.xxx | D17: xxx.xxx
B18: Desempeño | C18: xxx.xxx | D18: xxx.xxx
B19: Errores Triviales | C19: xxx.xxx | D19: xxx.xxx
B22: Procedimientos:
A24: 1.- | B24: Solicitar el detalle de préstamos bancarios
A25: 2.- | B25: Realizar los respectivos recálculos de las tablas de amortización
A26: 3.- | B26: Cruzar el gasto, pasivos corrientes y no corrientes con el estado de situación financiera.
A27: 4.- | B27: Documentar el papel de trabajo y concluir en función del objetivo. | S27: Valores completados en base al recálculo de la tabla de amortización
B29: Desarrollo:
B32: Nro. | C32: Institución financiera | D32: Nro. de operación | E32: Tipo de operación | F32: Fecha de préstamo | H32: Días plazo | I32: Garantía otorgada | J32: Monto de préstamo | K32: Ref. | L32: Saldo al _/_/20xx | N32: Saldo según confirmaciones | O32: Ref. | P32: Diferencia | R32: Gasto | S32: Ref. | T32: Pasivo interés | U32: Pasivo de capital corto plazo | V32: Pasivo de capital largo plazo
F33: Concesión | G33: Vencimiento
E35: 0 | F35: 0 | G35: 0 | H35: 0 | I35: 0 | J35: 0 | L35: 0 | P35: =+J35-N35 -> 0 | R35: =+'330.05.02'!I45 -> 0 | T35: =+'330.05.02'!I46 -> 0 | U35: =+GETPIVOTDATA("Capital",'330.05.02'!$B$50,"Clasificación","Corto Plazo") -> 0 | V35: =+GETPIVOTDATA("Capital",'330.05.02'!$B$50,"Clasificación","Largo Plazo") -> 0
E36: 0 | F36: 0 | G36: 0 | H36: 0 | I36: 0 | J36: 0 | L36: 0 | P36: =+J36-N36 -> 0 | R36: =+'330.05.02'!I45 -> 0 | T36: =+'330.05.02'!I46 -> 0 | U36: 0 | V36: 0
E37: 0 | F37: 0 | G37: 0 | H37: 0 | I37: 0 | J37: 0 | L37: 0 | P37: =+J37-N37 -> 0 | R37: 0 | T37: 0 | U37: 0 | V37: 0
E38: 0 | F38: 0 | G38: 0 | H38: 0 | I38: 0 | J38: 0 | L38: 0 | P38: =+J38-N38 -> 0 | R38: 0 | T38: 0 | U38: 0 | V38: 0
E39: 0 | F39: 0 | G39: 0 | H39: 0 | I39: 0 | J39: 0 | L39: 0 | P39: =+J39-N39 -> 0 | R39: 0 | T39: 0 | U39: 0 | V39: 0
E40: 0 | F40: 0 | G40: 0 | H40: 0 | I40: 0 | J40: 0 | L40: 0 | P40: =+J40-N40 -> 0 | R40: 0 | T40: 0 | U40: 0 | V40: 0
E41: 0 | F41: 0 | G41: 0 | H41: 0 | I41: 0 | J41: 0 | L41: 0 | P41: =+J41-N41 -> 0 | R41: 0 | T41: 0 | U41: 0 | V41: 0
E42: 0 | F42: 0 | G42: 0 | H42: 0 | I42: 0 | J42: 0 | L42: 0 | P42: =+J42-N42 -> 0 | R42: 0 | T42: 0 | U42: 0 | V42: 0
E43: 0 | F43: 0 | G43: 0 | H43: 0 | I43: 0 | L43: 0 | P43: =+J43-N43 -> 0 | R43: 0 | T43: 0 | U43: 0 | V43: 0
L44: 0 | P44: =+J44-N44 -> 0 | R44: 0 | T44: 0 | U44: 0 | V44: 0
L46: =SUM(L35:L45) -> 0 | P46: =SUM(P35:P45) -> 0 | R46: =SUM(R35:R45) -> 0 | T46: =SUM(T35:T45) -> 0 | U46: =SUM(U35:U45) -> 0 | V46: =SUM(V35:V45) -> 0
B50: Cruce con estados financieros
B52: 1) Cruce del detalle del pasivo préstamos vs estado de situación financiera
B54: Código cuenta contable | C54: Nombre cuenta contable | D54: Saldo según EEFF al _/_/20xx
B55: 0 | C55: 0 | D55: 0
B56: 0 | C56: 0 | D56: 0
D58: =SUM(D55:D56) -> 0 | E58: p/t 1600
C60: Saldo según detalle préstamos | D60: =+L46 -> 0
C61: Diferencia | D61: =+D58-D60 -> 0
B64: 2) Cruce del recálculo de intereses vs estado de resultados
...

Sheet 330.05.02
L3: Preparado por: | M3: Revisado por: | N3: Ref.
B4: COMPAÑÍA MODELO S.A. | L4: XX | M4: XX | N4: 330.05.02
B5: RECÁLCULO TABLAS DE AMORTIZACIÓN
B6: AL 31 DE DICIEMBRE DE 20XX
B7: FECHA DE CORTE: _ / _ / 20XX
B10: Objetivo:
B12: Verificar la razonabilidad y exactitud de las tablas de amortización al _ / _ / 20XX
B14: Base de decisión: Materialidad
C16: Preliminar | D16: Final
B17: General | C17: xxx.xxx | D17: xxx.xxx
B18: Desempeño | C18: xxx.xxx | D18: xxx.xxx
B19: Errores Triviales | C19: xxx.xxx | D19: xxx.xxx
B21: Procedimientos:
A23: 1.- | B23: Solicitar las tablas de amortización al _ / _ / 20XX
A24: 2.- | B24: Realizar el respectivo recálculo
A25: 3.- | B25: Documentar el papel de trabajo y concluir en base al objetivo.
B27: Desarrollo:
B29: Fecha inicio: | C29: _ /_ /20XX
B30: Fecha corte: | C30: _ /_ /20XX
B33: Nro. de serie | C33: Cuota | D33: Fecha de | E33: Días | F33: Tasa de | G33: Capital | H33: Clasificación | I33: Interés | J33: Pago | L33: Capital
D34: vencimiento | E34: transcurridos | F34: interés | L34: acumulado
E35: 0 | F35: 0 | G35: 0 | H35: =IF(E35>360,"Largo Plazo",IF(E35<360,"Corto Plazo",0)) -> Corto Plazo | L35: 0
C36: 1 | D36: _ /_ /2022 | G36: =+L35 -> 0 | H36: =IF(E36>360,"Largo Plazo",IF(E36<360,"Corto Plazo",0)) -> Corto Plazo | I36: =+G36*F36/100*(E36/360) -> 0 | J36: =+G36+I36 -> 0 | L36: =+L35-G36 -> 0
C37: 2 | D37: =+D36+E37 -> #VALUE! | G37: =+G36 -> 0 | H37: =IF(E37>360,"Largo Plazo",IF(E37<360,"Corto Plazo",0)) -> Corto Plazo | I37: =+G37*F37/100*(E37/360) -> 0 | J37: =+G37+I37 -> 0 | L37: =+L36-G37 -> 0
C38: 3 | D38: =+D37+E38 -> #VALUE! | G38: =+G37 -> 0 | H38: =IF(E38>360,"Largo Plazo",IF(E38<360,"Corto Plazo",0)) -> Corto Plazo | I38: =+G38*F38/100*(E38/360) -> 0 | J38: =+G38+I38 -> 0 | L38: =+L37-G38 -> 0
C39: 4 | D39: =+D38+E39 -> #VALUE! | G39: =+G38 -> 0 | H39: =IF(E39>360,"Largo Plazo",IF(E39<360,"Corto Plazo",0)) -> Corto Plazo | I39: =+G39*F39/100*(E39/360) -> 0 | J39: =+G39+I39 -> 0 | L39: =+L38-G39 -> 0
C40: 5 | D40: =+D39+E40 -> #VALUE! | G40: =+G39 -> 0 | H40: =IF(E40>360,"Largo Plazo",IF(E40<360,"Corto Plazo",0)) -> Corto Plazo | I40: =+G40*F40/100*(E40/360) -> 0 | J40: =+G40+I40 -> 0 | L40: =+L39-G40 -> 0
H42: =+SUM(H36:H40) -> 0 | I42: =+SUM(I36:I40) -> 0 | J42: =+SUM(J36:J40) -> 0
H44: Total saldo pagado | I44: =+J42 -> 0
H45: Total gasto interes | I45: =+I42 -> 0 | J45: p/t330.03
H46: Total provisión interes | I46: =SUM(I36:I37) -> 0 | J46: p/t330.03
B48: Resumen pasivo corto plazo y largo plazo
B50: Agrupación
B51: Clasificación | C51: Total
B52: 0
B53: Corto Plazo | C53: 0 | D53: p/t330.05.01
B55: Largo Plazo | C55: 0 | D55: p/t330.05.01
B56: Total general | C56: 0
B60: Marcas de auditoría:
B62: Sumatoria
...
