Workbook

Sheet 11.03
S2: Preparado por: | T2: Revisado por: | U2: Ref.
S3: XX | T3: XX | U3: 11.03
B6: COMPAÑÍA MODELO S.A.
B7: ANÁLISIS ACTIVO POR DERECHO DE USO Y PASIVO POR ARRENDAMIENTO
B8: AL 31 DE DICIEMBRE DE 20XX
B9: FECHA AL CORTE: _/_/20XX
B12: Objetivo:
B14: Verificar la valuación del activo por derecho de uso al _/_/20XX.
B16: Base de decisión: Materialidad
C19: Preliminar | D19: Final
B20: General | C20: XXX.XXX | D20: XXX.XXX
B21: Desempeño | C21: XXX.XXX | D21: XXX.XXX
B22: Errores Triviales | C22: XXX.XXX | D22: XXX.XXX
B24: Procedimiento:
A26: 1.- | B26: Solicitar a la Compañía los estado financieros al _/ _/ 20xx.
A27: 2.- | B27: Solicitar a la Compañía el detalle del cálculo del activo por derecho de Uso.
A28: 3.- | B28: Realizar el recálculo de los valores de acuerdo al contrato de arrendamiento.
A29: 4.- | B29: Conciliar el saldo del detalle y del recálculo con estados financieros.
A30: 5.- | B30: Documentar el papel de trabajo y concluir base al objetivo.
B33: Desarrollo:
F36: ***El cliente entregara por cada contrato su análisis respectivo (tabla de amortización)
F37: ***El formato de esta sección depende de cada cliente
F38: ***El número de filas depende del plazo del contrato
C42: Plazo en años | D42: xxxxxxxxx | G42: Meses hasta vencimiento | I42: xxxxxxxxx | M42: Tasa | N42: =+D45/12 -> 0
C43: Inicia | D43: xxxxxxxxx | G43: Valor canon mensual | I43: 0 | M43: Valor presente | N43: =+NPV(N42,N48:N59) -> 0 | O43: [1]
C44: Termina | D44: xxxxxxxxx | G44: Total Canon | I44: 0
C45: Tasa Anual | D45: 0
B47: Mes | C47: Período | D47: Saldo inicial | E47: Valor presente | F47: Período | G47: Saldo inicial | H47: Capital | I47: Interés | J47: Canon | K47: Saldo final | M47: Inicial | N47: Cuota | O47: Interés | P47: Saldo final | Q47: Depreciación | S47: Diferencia cuota | T47: Diferencia capital | U47: Diferencia interés
M48: =+N43 -> 0 | N48: =+I43 -> 0 | O48: =+M48*$N$42 -> 0 | P48: =+M48+O48-N48 -> 0 | Q48: =+$M$48/$J$42 -> #DIV/0! | S48: =+J48-N48 -> 0 | T48: =+H48-P48 -> 0 | U48: =+I48-O48 -> 0
M49: =+P48 -> 0 | N49: =+N48 -> 0 | O49: =+M49*$N$42 -> 0 | P49: =+M49+O49-N49 -> 0 | Q49: =+$M$48/$J$42 -> #DIV/0! | S49: =+J49-N49 -> 0 | T49: =+H49-P49 -> 0 | U49: =+I49-O49 -> 0
M50: =+P49 -> 0 | N50: =+N49 -> 0 | O50: =+M50*$N$42 -> 0 | P50: =+M50+O50-N50 -> 0 | Q50: =+$M$48/$J$42 -> #DIV/0! | S50: =+J50-N50 -> 0 | T50: =+H50-P50 -> 0 | U50: =+I50-O50 -> 0
M51: =+P50 -> 0 | N51: =+N50 -> 0 | O51: =+M51*$N$42 -> 0 | P51: =+M51+O51-N51 -> 0 | Q51: =+$M$48/$J$42 -> #DIV/0! | S51: =+J51-N51 -> 0 | T51: =+H51-P51 -> 0 | U51: =+I51-O51 -> 0
M52: =+P51 -> 0 | N52: =+N51 -> 0 | O52: =+M52*$N$42 -> 0 | P52: =+M52+O52-N52 -> 0 | Q52: =+$M$48/$J$42 -> #DIV/0! | S52: =+J52-N52 -> 0 | T52: =+H52-P52 -> 0 | U52: =+I52-O52 -> 0
M53: =+P52 -> 0 | N53: =+N52 -> 0 | O53: =+M53*$N$42 -> 0 | P53: =+M53+O53-N53 -> 0 | Q53: =+$M$48/$J$42 -> #DIV/0! | S53: =+J53-N53 -> 0 | T53: =+H53-P53 -> 0 | U53: =+I53-O53 -> 0
M54: =+P53 -> 0 | N54: =+N53 -> 0 | O54: =+M54*$N$42 -> 0 | P54: =+M54+O54-N54 -> 0 | Q54: =+$M$48/$J$42 -> #DIV/0! | S54: =+J54-N54 -> 0 | T54: =+H54-P54 -> 0 | U54: =+I54-O54 -> 0
M55: =+P54 -> 0 | N55: =+N54 -> 0 | O55: =+M55*$N$42 -> 0 | P55: =+M55+O55-N55 -> 0 | Q55: =+$M$48/$J$42 -> #DIV/0! | S55: =+J55-N55 -> 0 | T55: =+H55-P55 -> 0 | U55: =+I55-O55 -> 0
M56: =+P55 -> 0 | N56: =+N55 -> 0 | O56: =+M56*$N$42 -> 0 | P56: =+M56+O56-N56 -> 0 | Q56: =+$M$48/$J$42 -> #DIV/0! | S56: =+J56-N56 -> 0 | T56: =+H56-P56 -> 0 | U56: =+I56-O56 -> 0
M57: =+P56 -> 0 | N57: =+N56 -> 0 | O57: =+M57*$N$42 -> 0 | P57: =+M57+O57-N57 -> 0 | Q57: =+$M$48/$J$42 -> #DIV/0! | S57: =+J57-N57 -> 0 | T57: =+H57-P57 -> 0 | U57: =+I57-O57 -> 0
M58: =+P57 -> 0 | N58: =+N57 -> 0 | O58: =+M58*$N$42 -> 0 | P58: =+M58+O58-N58 -> 0 | Q58: =+$M$48/$J$42 -> #DIV/0! | S58: =+J58-N58 -> 0 | T58: =+H58-P58 -> 0 | U58: =+I58-O58 -> 0
M59: =+P58 -> 0 | N59: =+N58 -> 0 | O59: =+M59*$N$42 -> 0 | P59: =+M59+O59-N59 -> 0 | Q59: =+$M$48/$J$42 -> #DIV/0! | S59: =+J59-N59 -> 0 | T59: =+H59-P59 -> 0 | U59: =+I59-O59 -> 0
...

Sheet Análisis Imp.Diferido
D2: MECANOS SACI | J2: 2019
D3: NIIF 16 Arrendamientos
D4: Análisis de Impuesto Diferido
F8: Base | G8: Base
F9: Financiera | G9: Tributaria
D10: Mes | E10: Depreciacion | F10: Dep+Int | G10: V.Fact | H10: Dif.Temporal | I10: IR. Diferido
D11: 1 | E11: =+#REF! -> #REF! | F11: =+E11+'11.03'!I48 -> #REF! | G11: =+'11.03'!$J$43 -> 0 | H11: =+F11-G11 -> #REF! | I11: =+H11*25% -> #REF!
D12: =+D11+1 -> 2 | E12: =+#REF! -> #REF! | F12: =+E12+'11.03'!I49 -> #REF! | G12: =+'11.03'!$J$43 -> 0 | H12: =+F12-G12 -> #REF! | I12: =+H12*25% -> #REF!
D13: =+D12+1 -> 3 | E13: =+#REF! -> #REF! | F13: =+E13+'11.03'!I50 -> #REF! | G13: =+'11.03'!$J$43 -> 0 | H13: =+F13-G13 -> #REF! | I13: =+H13*25% -> #REF!
D14: =+D13+1 -> 4 | E14: =+#REF! -> #REF! | F14: =+E14+'11.03'!I51 -> #REF! | G14: =+'11.03'!$J$43 -> 0 | H14: =+F14-G14 -> #REF! | I14: =+H14*25% -> #REF!
D15: =+D14+1 -> 5 | E15: =+#REF! -> #REF! | F15: =+E15+'11.03'!I52 -> #REF! | G15: =+'11.03'!$J$43 -> 0 | H15: =+F15-G15 -> #REF! | I15: =+H15*25% -> #REF!
D16: =+D15+1 -> 6 | E16: =+#REF! -> #REF! | F16: =+E16+'11.03'!I53 -> #REF! | G16: =+'11.03'!$J$43 -> 0 | H16: =+F16-G16 -> #REF! | I16: =+H16*25% -> #REF!
D17: =+D16+1 -> 7 | E17: =+#REF! -> #REF! | F17: =+E17+'11.03'!I54 -> #REF! | G17: =+'11.03'!$J$43 -> 0 | H17: =+F17-G17 -> #REF! | I17: =+H17*25% -> #REF!
D18: =+D17+1 -> 8 | E18: =+#REF! -> #REF! | F18: =+E18+'11.03'!I55 -> #REF! | G18: =+'11.03'!$J$43 -> 0 | H18: =+F18-G18 -> #REF! | I18: =+H18*25% -> #REF!
D19: =+D18+1 -> 9 | E19: =+#REF! -> #REF! | F19: =+E19+'11.03'!I56 -> #REF! | G19: =+'11.03'!$J$43 -> 0 | H19: =+F19-G19 -> #REF! | I19: =+H19*25% -> #REF!
D20: =+D19+1 -> 10 | E20: =+#REF! -> #REF! | F20: =+E20+'11.03'!I57 -> #REF! | G20: =+'11.03'!$J$43 -> 0 | H20: =+F20-G20 -> #REF! | I20: =+H20*25% -> #REF!
D21: =+D20+1 -> 11 | E21: =+#REF! -> #REF! | F21: =+E21+'11.03'!I58 -> #REF! | G21: =+'11.03'!$J$43 -> 0 | H21: =+F21-G21 -> #REF! | I21: =+H21*25% -> #REF!
D22: =+D21+1 -> 12 | E22: =+#REF! -> #REF! | F22: =+E22+'11.03'!I59 -> #REF! | G22: =+'11.03'!$J$43 -> 0 | H22: =+F22-G22 -> #REF! | I22: =+H22*25% -> #REF!
F24: =SUM(F11:F23) -> #REF! | G24: =SUM(G11:G23) -> 0 | H24: =SUM(H11:H22) -> #REF! | I24: =SUM(I11:I22) -> #REF!
D26: =+D22+1 -> 13 | E26: =+#REF! -> #REF! | F26: =+E26+'11.03'!#REF! -> #REF! | G26: =+'11.03'!$J$43 -> 0 | H26: =+F26-G26 -> #REF! | I26: =+H26*25% -> #REF!
D27: =+D26+1 -> 14 | E27: =+#REF! -> #REF! | F27: =+E27+'11.03'!#REF! -> #REF! | G27: =+'11.03'!$J$43 -> 0 | H27: =+F27-G27 -> #REF! | I27: =+H27*25% -> #REF!
D28: =+D27+1 -> 15 | E28: =+#REF! -> #REF! | F28: =+E28+'11.03'!#REF! -> #REF! | G28: =+'11.03'!$J$43 -> 0 | H28: =+F28-G28 -> #REF! | I28: =+H28*25% -> #REF!
D29: =+D28+1 -> 16 | E29: =+#REF! -> #REF! | F29: =+E29+'11.03'!#REF! -> #REF! | G29: =+'11.03'!$J$43 -> 0 | H29: =+F29-G29 -> #REF! | I29: =+H29*25% -> #REF!
D30: =+D29+1 -> 17 | E30: =+#REF! -> #REF! | F30: =+E30+'11.03'!#REF! -> #REF! | G30: =+'11.03'!$J$43 -> 0 | H30: =+F30-G30 -> #REF! | I30: =+H30*25% -> #REF!
D31: =+D30+1 -> 18 | E31: =+#REF! -> #REF! | F31: =+E31+'11.03'!#REF! -> #REF! | G31: =+'11.03'!$J$43 -> 0 | H31: =+F31-G31 -> #REF! | I31: =+H31*25% -> #REF!
D32: =+D31+1 -> 19 | E32: =+#REF! -> #REF! | F32: =+E32+'11.03'!#REF! -> #REF! | G32: =+'11.03'!$J$43 -> 0 | H32: =+F32-G32 -> #REF! | I32: =+H32*25% -> #REF!
D33: =+D32+1 -> 20 | E33: =+#REF! -> #REF! | F33: =+E33+'11.03'!#REF! -> #REF! | G33: =+'11.03'!$J$43 -> 0 | H33: =+F33-G33 -> #REF! | I33: =+H33*25% -> #REF!
D34: =+D33+1 -> 21 | E34: =+#REF! -> #REF! | F34: =+E34+'11.03'!#REF! -> #REF! | G34: =+'11.03'!$J$43 -> 0 | H34: =+F34-G34 -> #REF! | I34: =+H34*25% -> #REF!
D35: =+D34+1 -> 22 | E35: =+#REF! -> #REF! | F35: =+E35+'11.03'!#REF! -> #REF! | G35: =+'11.03'!$J$43 -> 0 | H35: =+F35-G35 -> #REF! | I35: =+H35*25% -> #REF!
D36: =+D35+1 -> 23 | E36: =+#REF! -> #REF! | F36: =+E36+'11.03'!#REF! -> #REF! | G36: =+'11.03'!$J$43 -> 0 | H36: =+F36-G36 -> #REF! | I36: =+H36*25% -> #REF!
D37: =+D36+1 -> 24 | E37: =+#REF! -> #REF! | F37: =+E37+'11.03'!#REF! -> #REF! | G37: =+'11.03'!$J$43 -> 0 | H37: =+F37-G37 -> #REF! | I37: =+H37*25% -> #REF!
D38: =+D37+1 -> 25 | E38: =+#REF! -> #REF! | F38: =+E38+'11.03'!#REF! -> #REF! | G38: =+'11.03'!$J$43 -> 0 | H38: =+F38-G38 -> #REF! | I38: =+H38*25% -> #REF!
... D42: =+D41+1 -> 29 | E42: =+#REF! -> #REF! | F42: =+E42+'11.03'!#REF! -> #REF! | G42: =+'11.03'!$J$43 -> 0 | H42: =+F42-G42 -> #REF! | I42: =+H42*25% -> #REF!
D43: 30 | E43: =+#REF! -> #REF! | F43: =+E43+'11.03'!#REF! -> #REF! | G43: =+'11.03'!$J$43 -> 0 | H43: =+F43-G43 -> #REF! | I43: =+H43*25% -> #REF!
F45: =SUM(F26:F43) -> #REF! | G45: =SUM(G26:G43) -> 0 | H45: =SUM(H26:H43) -> #REF! | I45: =SUM(I26:I43) -> #REF!
F47: =+SUM(F11:F22,F26:F43) -> #REF! | G47: =+SUM(G11:G22,G26:G43) -> 0 | H47: =+SUM(H11:H22,H26:H43) -> #REF! | I47: =+SUM(I11:I22,I26:I43) -> #REF!
